<?xml version="1.0"?>
<robot name="driller">

  <link name="map"/>

  <link name="odom"/>
  <joint name="map_to_odom" type="fixed">
    <parent link="map"/>
    <child link="odom"/>
  </joint>

  <link name="base_link"/>
  <joint name="odom_to_camera_link" type="fixed">
    <parent link="odom"/>
    <child link="camera_link"/>
  </joint>

  <link name="camera_link"/>


  <joint name="camera_to_robot" type="fixed">
    <parent link="camera_link"/>
    <child link="base_link"/>
    <origin xyz="-0.12 0 -0.08" rpy="0 0 1.57075"/>
  </joint>

  <joint name="base_link_to_chassis" type="fixed">
    <parent link="base_link"/>
    <child link="robot_chassis"/>
  </joint>

  <link name="robot_chassis">
    <visual>
      <geometry>
         <mesh filename="package://robot_model/meshes/base_link.dae" scale="0.1 0.1 0.1"/>
      </geometry>
      <origin rpy="0 0 0" xyz="-0.0072 0 0"/>
    </visual>
    <collision>
      <origin xyz="0 0.022 0.025" rpy="0 0 0"/>
      <geometry>
        <box size="0.15 0.3 0.05" />
      </geometry>
    </collision>
    <inertial>
      <mass value="3"/>
      <inertia ixx="0.4" ixy="0.0" ixz="0.0" iyy="0.4" iyz="0.0" izz="0.2"/>
    </inertial>
  </link>

  <link name="left_upper_leg">
    <visual>
      <geometry>
         <mesh filename="package://robot_model/meshes/wheel_arm.dae" scale="0.1 0.1 0.1"/>
      </geometry>
      <origin rpy="0.33 0 1.57075" xyz="0 0 0"/>
    </visual>
    <inertial>
      <mass value="0.1"/>
      <inertia ixx="0.1" ixy="0.0" ixz="0.0" iyy="0.1" iyz="0.0" izz="0.1"/>
    </inertial>
  </link>
  <joint name="base_to_left_upper_leg" type="fixed">
    <parent link="robot_chassis"/>
    <child link="left_upper_leg"/>
    <origin xyz="0.029 0.152 0.042"/>
  </joint>

  <link name="left_lower_leg">
    <visual>
      <geometry>
         <mesh filename="package://robot_model/meshes/wheel_arm.dae" scale="0.1 0.1 0.1"/>
      </geometry>
      <origin rpy="0.33 0 1.57075" xyz="0 0 0"/>
    </visual>
    <inertial>
      <mass value="0.1"/>
      <inertia ixx="0.1" ixy="0.0" ixz="0.0" iyy="0.1" iyz="0.0" izz="0.1"/>
    </inertial>
  </link>
  <joint name="base_to_left_lower_leg" type="fixed">
    <parent link="robot_chassis"/>
    <child link="left_lower_leg"/>
    <origin xyz="0.029 0.152 0.01"/>
  </joint>

  <link name="left_wheel_leg">
    <visual>
      <geometry>
         <mesh filename="package://robot_model/meshes/wheel.dae" scale="0.1 0.1 0.1"/>
      </geometry>
      <origin rpy="0 1.57075 0" xyz="0 0 0"/>
    </visual>
    <inertial>
      <mass value="0.4"/>
      <inertia ixx="0.2" ixy="0.0" ixz="0.0" iyy="0.2" iyz="0.0" izz="0.2"/>
    </inertial>
   <collision>
     <origin xyz="0.018 0 0" rpy="0 1.57075 0"/>
     <geometry>
       <cylinder radius="0.035" length="0.022"/>
     </geometry>
   </collision>
  </link>
  <joint name="base_to_left_wheel_leg" type="continuous">
    <parent link="robot_chassis"/>
    <child link="left_wheel_leg"/>
    <axis xyz="1 0 0"/>
    <origin xyz="0.09 0.152 0.005"/>
  </joint>
  <transmission name="left_leg_rotator">
    <type>transmission_interface/SimpleTransmission</type>
    <actuator name="left_leg_motor">
      <mechanicalReduction>1</mechanicalReduction>
    </actuator>
    <joint name="base_to_left_wheel_leg">
      <hardwareInterface>VelocityJointInterface</hardwareInterface>
    </joint>
  </transmission>
    <gazebo reference="left_wheel_leg">
      <mu1 value="200.0"/>
      <mu2 value="100.0"/>
      <kp value="10000000.0" />
      <kd value="1.0" />
      <material>Gazebo/Grey</material>
    </gazebo>

  <link name="right_upper_leg">
    <visual>
      <geometry>
         <mesh filename="package://robot_model/meshes/wheel_arm.dae" scale="0.1 0.1 0.1"/>
      </geometry>
      <origin rpy="2.8115 0 1.57075" xyz="0 0 0"/>
    </visual>
    <inertial>
      <mass value="0.1"/>
      <inertia ixx="0.1" ixy="0.0" ixz="0.0" iyy="0.1" iyz="0.0" izz="0.1"/>
    </inertial>
  </link>
  <joint name="base_to_right_upper_leg" type="fixed">
    <parent link="robot_chassis"/>
    <child link="right_upper_leg"/>
    <origin xyz="-0.029 0.152 0.042"/>
  </joint>

  <link name="right_lower_leg">
    <visual>
      <geometry>
         <mesh filename="package://robot_model/meshes/wheel_arm.dae" scale="0.1 0.1 0.1"/>
      </geometry>
      <origin rpy="2.8115 0 1.57075" xyz="0 0 0"/>
    </visual>
    <inertial>
      <mass value="0.1"/>
      <inertia ixx="0.1" ixy="0.0" ixz="0.0" iyy="0.1" iyz="0.0" izz="0.1"/>
    </inertial>
  </link>
  <joint name="base_to_right_lower_leg" type="fixed">
    <parent link="robot_chassis"/>
    <child link="right_lower_leg"/>
    <origin xyz="-0.029 0.152 0.01"/>
  </joint>

  <link name="right_wheel_leg">
    <visual>
      <geometry>
         <mesh filename="package://robot_model/meshes/wheel.dae" scale="0.1 0.1 0.1"/>
      </geometry>
      <origin rpy="0 -1.57075 0" xyz="0 0 0"/>
    </visual>
    <inertial>
      <mass value="0.4"/>
      <inertia ixx="0.2" ixy="0.0" ixz="0.0" iyy="0.2" iyz="0.0" izz="0.2"/>
    </inertial>
   <collision>
     <origin xyz="-0.018 0 0" rpy="0 1.57075 0"/>
     <geometry>
       <cylinder radius="0.035" length="0.022"/>
     </geometry>
   </collision>
  </link>
  <joint name="base_to_right_wheel_leg" type="continuous">
    <parent link="robot_chassis"/>
    <child link="right_wheel_leg"/>
    <axis xyz="1 0 0"/>
    <origin xyz="-0.09 0.152 0.005"/>
    <limit effort="30" velocity="1.0"/>
  </joint>
  <transmission name="right_leg_rotator">
    <type>transmission_interface/SimpleTransmission</type>
    <actuator name="right_leg_motor">
      <mechanicalReduction>1</mechanicalReduction>
    </actuator>
    <joint name="base_to_right_wheel_leg">
      <hardwareInterface>VelocityJointInterface</hardwareInterface>
    </joint>
  </transmission>
    <gazebo reference="right_wheel_leg">
      <mu1 value="200.0"/>
      <mu2 value="100.0"/>
      <kp value="10000000.0" />
      <kd value="1.0" />
      <material>Gazebo/Grey</material>
    </gazebo>

  <link name="left_upper_arm">
    <visual>
      <geometry>
         <mesh filename="package://robot_model/meshes/wheel_arm.dae" scale="0.1 0.1 0.1"/>
      </geometry>
      <origin rpy="-0.33 3.1415 1.57075" xyz="0 0 0"/>
    </visual>
    <inertial>
      <mass value="0.1"/>
      <inertia ixx="0.1" ixy="0.0" ixz="0.0" iyy="0.1" iyz="0.0" izz="0.1"/>
    </inertial>
  </link>
  <joint name="base_to_left_upper_arm" type="fixed">
    <parent link="robot_chassis"/>
    <child link="left_upper_arm"/>
    <origin xyz="0.029 -0.095 0.042"/>
  </joint>

  <link name="left_lower_arm">
    <visual>
      <geometry>
         <mesh filename="package://robot_model/meshes/wheel_arm.dae" scale="0.1 0.1 0.1"/>
      </geometry>
      <origin rpy="-0.33 3.1415 1.57075" xyz="0 0 0"/>
    </visual>
    <inertial>
      <mass value="0.1"/>
      <inertia ixx="0.1" ixy="0.0" ixz="0.0" iyy="0.1" iyz="0.0" izz="0.1"/>
    </inertial>
  </link>
  <joint name="base_to_left_lower_arm" type="fixed">
    <parent link="robot_chassis"/>
    <child link="left_lower_arm"/>
    <origin xyz="0.029 -0.095 0.01"/>
  </joint>

  <link name="left_wheel_steering">
    <visual>
      <geometry>
         <mesh filename="package://robot_model/meshes/front_steer.dae" scale="0.1 0.1 0.1"/>
      </geometry>
      <origin rpy="0 0 0" xyz="0 0 0"/>
    </visual>
    <inertial>
      <mass value="0.1"/>
      <inertia ixx="0.1" ixy="0.0" ixz="0.0" iyy="0.1" iyz="0.0" izz="0.1"/>
    </inertial>
  </link>
  <joint name="base_to_left_wheel_steering" type="revolute">
    <parent link="robot_chassis"/>
    <child link="left_wheel_steering"/>
    <limit effort="1000.0" lower="-0.4" upper="0.4" velocity="0.5"/>
    <axis xyz="0 0 1"/>
    <origin xyz="0.085 -0.095 0.005"/>
    <limit effort="30" velocity="1.0"/>
  </joint>
  <transmission name="left_wheel_steering_rot">
    <type>transmission_interface/SimpleTransmission</type>
    <actuator name="left_wheel_steering_motor">
      <mechanicalReduction>1</mechanicalReduction>
    </actuator>
    <joint name="base_to_left_wheel_steering">
      <hardwareInterface>PositionJointInterface</hardwareInterface>
    </joint>
  </transmission>

  <link name="left_wheel_arm">
    <visual>
      <geometry>
         <mesh filename="package://robot_model/meshes/wheel.dae" scale="0.1 0.1 0.1"/>
      </geometry>
      <origin rpy="0 1.57075 0" xyz="0 0 0"/>
    </visual>
    <inertial>
      <mass value="0.4"/>
      <inertia ixx="0.2" ixy="0.0" ixz="0.0" iyy="0.2" iyz="0.0" izz="0.2"/>
    </inertial>
   <collision>
     <origin xyz="0.018 0 0" rpy="0 1.57075 0"/>
     <geometry>
       <cylinder radius="0.035" length="0.022"/>
     </geometry>
   </collision>
  </link>
  <joint name="base_to_left_wheel_arm" type="continuous">
    <parent link="left_wheel_steering"/>
    <child link="left_wheel_arm"/>
    <axis xyz="1 0 0"/>
    <origin xyz="0.005 0 0"/>
  </joint>
    <gazebo reference="left_wheel_arm">
      <mu1 value="200.0"/>
      <mu2 value="100.0"/>
      <kp value="10000000.0" />
      <kd value="1.0" />
      <material>Gazebo/Grey</material>
    </gazebo>

  <link name="right_upper_arm">
    <visual>
      <geometry>
         <mesh filename="package://robot_model/meshes/wheel_arm.dae" scale="0.1 0.1 0.1"/>
      </geometry>
      <origin rpy="3.4715 3.1415 1.57075" xyz="0 0 0"/>
    </visual>
    <inertial>
      <mass value="0.1"/>
      <inertia ixx="0.1" ixy="0.0" ixz="0.0" iyy="0.1" iyz="0.0" izz="0.1"/>
    </inertial>
  </link>
  <joint name="base_to_right_upper_arm" type="fixed">
    <parent link="robot_chassis"/>
    <child link="right_upper_arm"/>
    <origin xyz="-0.029 -0.095 0.042"/>
  </joint>

  <link name="right_lower_arm">
    <visual>
      <geometry>
         <mesh filename="package://robot_model/meshes/wheel_arm.dae" scale="0.1 0.1 0.1"/>
      </geometry>
      <origin rpy="3.4715 3.1415 1.57075" xyz="0 0 0"/>
    </visual>
    <inertial>
      <mass value="0.1"/>
      <inertia ixx="0.1" ixy="0.0" ixz="0.0" iyy="0.1" iyz="0.0" izz="0.1"/>
    </inertial>
  </link>
  <joint name="base_to_right_lower_arm" type="fixed">
    <parent link="robot_chassis"/>
    <child link="right_lower_arm"/>
    <origin xyz="-0.029 -0.095 0.01"/>
  </joint>

  <link name="right_wheel_steering">
    <visual>
      <geometry>
         <mesh filename="package://robot_model/meshes/front_steer.dae" scale="0.1 0.1 0.1"/>
      </geometry>
      <origin rpy="0 3.1415 0" xyz="0 0 0"/>
    </visual>
    <inertial>
      <mass value="0.1"/>
      <inertia ixx="0.1" ixy="0.0" ixz="0.0" iyy="0.1" iyz="0.0" izz="0.1"/>
    </inertial>
  </link>
  <joint name="base_to_right_wheel_steering" type="revolute">
    <parent link="robot_chassis"/>
    <child link="right_wheel_steering"/>
    <limit effort="1000.0" lower="-0.4" upper="0.4" velocity="0.5"/>
    <axis xyz="0 0 1"/>
    <origin xyz="-0.085 -0.095 0.005"/>
    <limit effort="30" velocity="1.0"/>
  </joint>
  <transmission name="right_wheel_steering_rot">
    <type>transmission_interface/SimpleTransmission</type>
    <actuator name="right_wheel_steering_motor">
      <mechanicalReduction>1</mechanicalReduction>
    </actuator>
    <joint name="base_to_right_wheel_steering">
      <hardwareInterface>PositionJointInterface</hardwareInterface>
    </joint>
  </transmission>

  <link name="right_wheel_arm">
    <visual>
      <geometry>
         <mesh filename="package://robot_model/meshes/wheel.dae" scale="0.1 0.1 0.1"/>
      </geometry>
      <origin rpy="0 -1.57075 0" xyz="0 0 0"/>
    </visual>
    <inertial>
      <mass value="0.4"/>
      <inertia ixx="0.2" ixy="0.0" ixz="0.0" iyy="0.2" iyz="0.0" izz="0.2"/>
    </inertial>
   <collision>
     <origin xyz="-0.018 0 0" rpy="0 1.57075 0"/>
     <geometry>
       <cylinder radius="0.035" length="0.022"/>
     </geometry>
   </collision>
  </link>
  <joint name="base_to_right_wheel_arm" type="continuous">
    <parent link="right_wheel_steering"/>
    <child link="right_wheel_arm"/>
    <axis xyz="1 0 0"/>
    <origin xyz="-0.005 0 0"/>
  </joint>
    <gazebo reference="right_wheel_arm">
      <mu1 value="200.0"/>
      <mu2 value="100.0"/>
      <kp value="10000000.0" />
      <kd value="1.0" />
      <material>Gazebo/Grey</material>
    </gazebo>

  <gazebo>
    <plugin name="gazebo_ros_control" filename="libgazebo_ros_control.so">
      <robotNamespace>/</robotNamespace>
    </plugin>
  </gazebo>

</robot>
